Workbook

Sheet Приложение 1
G1: Приложение 1
F2: УТВЕРЖДАЮ
F3: руководитель ГБУ КК "Центр развития спорта"
F4: ______________ В.П. Колпаков
F5: согласно приказу
F6: № ____ от "____"_______ 20___ г.
G7: _
A8: Календарный план официальных физкультурных и спортивных мероприятий государственного бюджетного учреждения Краснодарского края "Центр развития спорта" на 2026 год в части обеспечения наградной атрибутикой за счет субсидий на финансовое обеспечение выполнения государственного задания на оказание государственных услуг (выполнение работ) в 2026 году | Z8: УТВЕРЖДАЮ
A10: № п/п | B10: Наименование мероприятия | C10: Вид соревнований | D10: Возраст | E10: Дата проведения (начало мероприятия) | F10: Дата проведения (конец мероприятия) | G10: Место проведения | H10: Количество кубков | Q10: Количество медалей | Z10: Грамоты | AC10: Услуги по изготовлению и поставке | AE10: Всего по виду спорта
H11: 1 место Кол-во, шт. | I11: Стоимость 1 шт. | J11: Итого | K11: 2 место Кол-во, шт. | L11: Стоимость 1 шт. | M11: Итого | N11: 3 место Кол-во, шт. | O11: Стоимость 1 шт. | P11: Итого | Q11: 1 место Кол-во, шт. | R11: Стоимость 1 шт. | S11: Итого | T11: 2 место Кол-во, шт. | U11: Стоимость 1 шт. | V11: Итого | W11: 3 место Количество, шт. | X11: Стоимость 1 | Y11: Итого | Z11: Кол-во, шт. | AA11: Стоимость 1 шт. | AB11: Итого | AC11: Кол-во ед наградного материала | AD11: Сумма
B12: ФИЗКУЛЬТУРНЫЕ МЕРОПРИЯТИЯ СРЕДИ РАЗЛИЧНЫХ ВОЗРАСТНЫХ ГРУПП НАСЕЛЕНИЯ И ИНВАЛИДОВ
B13: ГОТОВ К ТРУДУ И ОБОРОНЕ
A14: 1 | B14: Краевой фестиваль Всероссийского физкультурно-спортивного комплекса «Готов к труду и обороне» (ГТО) среди семейных команд | C14: КС | D14: мальчики, девочки 9-10 лет, мужчины, женщины 25-64 года | E14: 46162 | F14: 46172 | G14: г. Туапсе | H14: 1 | I14: 3400 | J14: =H14*I14 -> 3400 | K14: 1 | L14: 3000 | M14: =K14*L14 -> 3000 | N14: 1 | O14: 2900 | P14: =N14*O14 -> 2900 | Q14: 4 | R14: 190 | S14: =Q14*R14 -> 760 | T14: 4 | U14: 190 | V14: =T14*U14 -> 760 | W14: 4 | X14: 190 | Y14: =W14*X14 -> 760 | Z14: 15 | AA14: 6 | AB14: =Z14*AA14 -> 90 | AC14: =H14+K14+N14+Q14+T14+W14+Z14 -> 30 | AD14: =J14+M14+P14+S14+V14+Y14+AB14 -> 11670 | AF14: 15
A15: 2 | B15: Краевой Фестиваль Всероссийского физкультурно-спортивного комплекса «Готов к труду и обороне» (ГТО) среди обучающихся образовательных организаций высшего образования | C15: КС | D15: от 18 до 24 лет | E15: 46066 | F15: 46066 | G15: Краснодарский край | H15: 1 | I15: 3400 | J15: =H15*I15 -> 3400 | K15: 1 | L15: 3000 | M15: =K15*L15 -> 3000 | N15: 1 | O15: 2900 | P15: =N15*O15 -> 2900 | Q15: 4 | R15: 190 | S15: =Q15*R15 -> 760 | T15: 4 | U15: 190 | V15: =T15*U15 -> 760 | W15: 4 | X15: 190 | Y15: =W15*X15 -> 760 | Z15: 15 | AA15: 6 | AB15: =Z15*AA15 -> 90 | AC15: =H15+K15+N15+Q15+T15+W15+Z15 -> 30 | AD15: =J15+M15+P15+S15+V15+Y15+AB15 -> 11670 | AF15: 27
A16: 3 | B16: Краевой Фестиваль Всероссийского физкультурно-спортивного комплекса «Готов к труду и обороне» (ГТО) среди граждан, проживающих в сельской местности | C16: КС | D16: от 16 до 49 лет | E16: 46193 | F16: 46193 | G16: Краснодарский край | H16: 1 | I16: 3400 | J16: =H16*I16 -> 3400 | K16: 1 | L16: 3000 | M16: =K16*L16 -> 3000 | N16: 1 | O16: 2900 | P16: =N16*O16 -> 2900 | Q16: 8 | R16: 190 | S16: =Q16*R16 -> 1520 | T16: 8 | U16: 190 | V16: =T16*U16 -> 1520 | W16: 8 | X16: 190 | Y16: =W16*X16 -> 1520 | Z16: 27 | AA16: 6 | AB16: =Z16*AA16 -> 162 | AC16: =H16+K16+N16+Q16+T16+W16+Z16 -> 54 | AD16: =J16+M16+P16+S16+V16+Y16+AB16 -> 14022
A17: 4 | B17: Физкультурное мероприятие "Всекубанский казачий слет "Готов к труду и обороне" | C17: КС | D17: от 20 до 49 лет | E17: 46305 | F17: 46305 | G17: Краснодарский край | H17: 1 | I17: 3400 | J17: =H17*I17 -> 3400 | K17: 1 | L17: 3000 | M17: =K17*L17 -> 3000 | N17: 1 | O17: 2900 | P17: =N17*O17 -> 2900 | Q17: 4 | R17: 190 | S17: =Q17*R17 -> 760 | T17: 4 | U17: 190 | V17: =T17*U17 -> 760 | W17: 4 | X17: 190 | Y17: =W17*X17 -> 760 | Z17: 15 | AA17: 6 | AB17: =Z17*AA17 -> 90 | AC17: =H17+K17+N17+Q17+T17+W17+Z17 -> 30 | AD17: =J17+M17+P17+S17+V17+Y17+AB17 -> 11670
A18: 5 | B18: Краевой фестиваль чемпионов Всероссийского физкультурно-спортивного комплекса "Готов к труду и обороне" | C18: КС | D18: от 18 до 49 | E18: 46291 | F18: 46291 | G18: Краснодарский край | H18: 1 | I18: 3400 | J18: =H18*I18 -> 3400 | K18: 1 | L18: 3000 | M18: =K18*L18 -> 3000 | N18: 1 | O18: 2900 | P18: =N18*O18 -> 2900 | Q18: 5 | R18: 190 | S18: =Q18*R18 -> 950 | T18: 5 | U18: 190 | V18: =T18*U18 -> 950 | W18: 5 | X18: 190 | Y18: =W18*X18 -> 950 | Z18: 15 | AA18: 6 | AB18: =Z18*AA18 -> 90 | AC18: =H18+K18+N18+Q18+T18+W18+Z18 -> 33 | AD18: =J18+M18+P18+S18+V18+Y18+AB18 -> 12240
A19: 6 | B19: Краевой день бега "Кросс Нации" в рамках Всероссийского дня бега "Кросс Нации" | C19: КС | D19: согласно положению | E19: сентябрь | F19: сентябрь | G19: согласно положению | Q19: 118 | R19: 190 | S19: =Q19*R19 -> 22420 | T19: 118 | U19: 190 | V19: =T19*U19 -> 22420 | W19: 118 | X19: 190 | Y19: =W19*X19 -> 22420 | Z19: 354 | AA19: 6 | AB19: =Z19*AA19 -> 2124 | AC19: =H19+K19+N19+Q19+T19+W19+Z19 -> 708 | AD19: =J19+M19+P19+S19+V19+Y19+AB19 -> 69384
A20: 7 | B20: Краевые соревнования по городошному спорту среди ветеранов физической культуры и спорта Кубани | C20: КС | D20: 35 лет и старше | E20: октябрь | F20: октябрь | G20: согласно положению | Q20: 6 | R20: 190 | S20: =Q20*R20 -> 1140 | T20: 6 | U20: 190 | V20: =T20*U20 -> 1140 | W20: 6 | X20: 190 | Y20: =W20*X20 -> 1140 | Z20: 18 | AA20: 6 | AB20: =Z20*AA20 -> 108 | AC20: =H20+K20+N20+Q20+T20+W20+Z20 -> 36 | AD20: =J20+M20+P20+S20+V20+Y20+AB20 -> 3528
A21: 8 | B21: Всекубанская эстафета «Спортсмены Кубани – в ознаменование Победы в Великой Отечественной войне 1941-1945 годов» | C21: КС | D21: согласно положению | E21: июнь | F21: июнь | G21: согласно положению | Q21: 118 | R21: 190 | S21: =Q21*R21 -> 22420 | T21: 118 | U21: 190 | V21: =T21*U21 -> 22420 | W21: 118 | X21: 190 | Y21: =W21*X21 -> 22420 | Z21: 354 | AA21: 6 | AB21: =Z21*AA21 -> 2124 | AC21: =H21+K21+N21+Q21+T21+W21+Z21 -> 708 | AD21: =J21+M21+P21+S21+V21+Y21+AB21 -> 69384
A22: 3 | B22: Краевой Фестиваль Всероссийского физкультурно-спортивного комплекса "Готов к труду и обороне" (ГТО) среди трудовых коллективов, посвященного празднованию 80-летия Победы советского народа в Великой Отечественной войне 1941-1945 годов | C22: КС | D22: мужчины, женщины 25-64 года | E22: 46067 | F22: 46067 | G22: Краснодарский край | H22: 1 | I22: 3300 | J22: =H22*I22 -> 3300 | K22: 1 | L22: 2850 | M22: =K22*L22 -> 2850 | N22: 1 | O22: 2750 | P22: =N22*O22 -> 2750 | Q22: 8 | R22: 190 | S22: =Q22*R22 -> 1520 | T22: 8 | U22: 190 | V22: =T22*U22 -> 1520 | W22: 8 | X22: 190 | Y22: =W22*X22 -> 1520 | Z22: 27 | AA22: 6 | AB22: =Z22*AA22 -> 162 | AE22: =H22+K22+N22+Q22+T22+W22+Z22 -> 54 | AF22: =J22+M22+P22+S22+V22+Y22+AB22 -> 13622 | AH22: положение 12.01.2026
A23: 4 | B23: Краевой фестиваль Всероссийского физкультурно-спортивного комплекса «Готов к труду и обороне» (ГТО) среди обучающихся профессиональных образовательных организаций | C23: КС | D23: юноши, девушки 16-19 лет | E23: 46066 | F23: 46066 | G23: Краснодарский край | H23: 1 | I23: 3300 | J23: =H23*I23 -> 3300 | K23: 1 | L23: 2850 | M23: =K23*L23 -> 2850 | N23: 1 | O23: 2750 | P23: =N23*O23 -> 2750 | Q23: 4 | R23: 190 | S23: =Q23*R23 -> 760 | T23: 4 | U23: 190 | V23: =T23*U23 -> 760 | W23: 4 | X23: 190 | Y23: =W23*X23 -> 760 | Z23: 15 | AA23: 6 | AB23: =Z23*AA23 -> 90 | AE23: =H23+K23+N23+Q23+T23+W23+AB23 -> 105 | AF23: =J23+M23+P23+S23+V23+Y23+AB23 -> 11270 | AH23: положение 12.01.2026
A24: 5 | B24: Краевые соревнования юных хоккеистов ,,Золотая шайба" | C24: КС | D24: 2013-2014 г.р. | E24: 46040 | F24: 46042 | G24: г.Горячий ключ | H24: 1 | I24: 3300 | J24: =H24*I24 -> 3300 | K24: 1 | L24: 2850 | M24: =K24*L24 -> 2850 | N24: 1 | O24: 2750 | P24: =N24*O24 -> 2750 | Q24: 19 | R24: 190 | S24: =Q24*R24 -> 3610 | T24: 19 | U24: 190 | V24: =T24*U24 -> 3610 | W24: 19 | X24: 190 | Y24: =W24*X24 -> 3610 | Z24: 60 | AA24: 6 | AB24: =Z24*AA24 -> 360 | AE24: =H24+K24+N24+Q24+T24+W24+Z24 -> 120 | AF24: =J24+M24+P24+S24+V24+Y24+AB24 -> 20090 | AH24: положение 24.12.2026
A25: 6 | B25: Краевые соревнования юных хоккеистов ,,Золотая шайба" | C25: КС | D25: 2015-2016 г.р. | E25: 46044 | F25: 46046 | G25: г.Горячий ключ | H25: 1 | I25: 3300 | J25: =H25*I25 -> 3300 | K25: 1 | L25: 2850 | M25: =K25*L25 -> 2850 | N25: 1 | O25: 2750 | P25: =N25*O25 -> 2750 | Q25: 19 | R25: 190 | S25: =Q25*R25 -> 3610 | T25: 19 | U25: 190 | V25: =T25*U25 -> 3610 | W25: 19 | X25: 190 | Y25: =W25*X25 -> 3610 | Z25: 60 | AA25: 6 | AB25: =Z25*AA25 -> 360 | AE25: =H25+K25+N25+Q25+T25+W25+Z25 -> 120 | AF25: =J25+M25+P25+S25+V25+Y25+AB25 -> 20090 | AH25: положение 24.12.2026
A26: 7 | B26: Краевые соревнования юных хоккеистов ,,Золотая шайба" | C26: КС | D26: 2009-2010 г.р. | E26: 46037 | F26: 46039 | G26: г.Краснодар | H26: 1 | I26: 3300 | J26: =H26*I26 -> 3300 | K26: 1 | L26: 2850 | M26: =K26*L26 -> 2850 | N26: 1 | O26: 2750 | P26: =N26*O26 -> 2750 | Q26: 19 | R26: 190 | S26: =Q26*R26 -> 3610 | T26: 19 | U26: 190 | V26: =T26*U26 -> 3610 | W26: 19 | X26: 190 | Y26: =W26*X26 -> 3610 | Z26: 60 | AA26: 6 | AB26: =Z26*AA26 -> 360 | AE26: =H26+K26+N26+Q26+T26+W26+Z26 -> 120 | AF26: =J26+M26+P26+S26+V26+Y26+AB26 -> 20090 | AH26: положение 24.12.2026
A27: 8 | B27: Краевые соревнования юных хоккеистов ,,Золотая шайба" | C27: КС | D27: 2009-2010 г.р. | E27: 46036 | F27: 46036 | G27: г.Краснодар | H27: 1 | I27: 3300 | J27: =H27*I27 -> 3300 | K27: 1 | L27: 2850 | M27: =K27*L27 -> 2850 | N27: 1 | O27: 2750 | P27: =N27*O27 -> 2750 | Q27: 19 | R27: 190 | S27: =Q27*R27 -> 3610 | T27: 19 | U27: 190 | V27: =T27*U27 -> 3610 | W27: 19 | X27: 190 | Y27: =W27*X27 -> 3610 | Z27: 60 | AA27: 6 | AB27: =Z27*AA27 -> 360 | AE27: =H27+K27+N27+Q27+T27+W27+Z27 -> 120 | AF27: =J27+M27+P27+S27+V27+Y27+AB27 -> 20090 | AH27: положение 24.12.2026
B28: ФИЗКУЛЬТУРНЫЕ МЕРОПРИЯТИЯ
A29: 9 | B29: XXXV Универсиада Кубани среди высших учебных заведений (по видам спорта) | C29: КС | D29: юноши, девушки 1999 - 2006 г.р. | E29: январь | F29: май | G29: г. Краснодар | H29: 11 | I29: 3400 | J29: =H29*I29 -> 37400 | K29: 11 | L29: 3000 | M29: =K29*L29 -> 33000 | N29: 11 | O29: 2900 | P29: =N29*O29 -> 31900 | Q29: 159 | R29: 190 | S29: =Q29*R29 -> 30210 | T29: 159 | U29: 190 | V29: =T29*U29 -> 30210 | W29: 257 | X29: 190 | Y29: =W29*X29 -> 48830 | Z29: 610 | AA29: 6 | AB29: =Z29*AA29 -> 3660 | AC29: =H29+K29+N29+Q29+T29+W29+Z29 -> 1218 | AD29: =J29+M29+P29+S29+V29+Y29+AB29 -> 215210
A30: 10 | B30: XVII Спартакиада среди сборных команд органов исполнительной власти и структурных подразделений администрации Краснодарского края (по видам спорта) | C30: КС | D30: 18 лет и старше | E30: февраль | F30: декабрь | G30: г. Краснодар | H30: 21 | I30: 3400 | J30: =H30*I30 -> 71400 | K30: 21 | L30: 3000 | M30: =K30*L30 -> 63000 | N30: 21 | O30: 2900 | P30: =N30*O30 -> 60900 | Q30: 149 | R30: 190 | S30: =Q30*R30 -> 28310 | T30: 149 | U30: 190 | V30: =T30*U30 -> 28310 | W30: 149 | X30: 190 | Y30: =W30*X30 -> 28310 | Z30: 522 | AA30: 6 | AB30: =Z30*AA30 -> 3132 | AC30: =H30+K30+N30+Q30+T30+W30+Z30 -> 1032 | AD30: =J30+M30+P30+S30+V30+Y30+AB30 -> 283362
A31: 11 | B31: XXXIII Сельские спортивные игры Кубани | C31: КС | D31: мужчины, женщины 18 лет и старше | E31: 46037 | F31: 46203 | G31: муниципальные образования Краснодарского края | H31: 20 | I31: 3400 | J31: =H31*I31 -> 68000 | K31: 20 | L31: 3000 | M31: =K31*L31 -> 60000 | N31: 20 | O31: 2900 | P31: =N31*O31 -> 58000 | Q31: 116 | R31: 190 | S31: =Q31*R31 -> 22040 | T31: 116 | U31: 190 | V31: =T31*U31 -> 22040 | W31: 116 | X31: 190 | Y31: =W31*X31 -> 22040 | Z31: 408 | AA31: 6 | AB31: =Z31*AA31 -> 2448 | AC31: 500 | AD31: =J31+M31+P31+S31+V31+Y31+AB31 -> 254568
A32: 12 | B32: Турнир Краснодарского края по волейболу среди команд ветеранов в честь Дня Защитника Отечества | C32: КС | D32: мужчины 40 лет и старше, женщины 35 лет и старше | E32: 46065 | F32: 46068 | G32: п. Ольгинка (Туапсинский район) | H32: 6 | I32: 3400 | J32: =H32*I32 -> 20400 | K32: 6 | L32: 3000 | M32: =K32*L32 -> 18000 | N32: 6 | O32: 2900 | P32: =N32*O32 -> 17400 | Q32: 60 | R32: 190 | S32: =Q32*R32 -> 11400 | T32: 60 | U32: 190 | V32: =T32*U32 -> 11400 | W32: 60 | X32: 190 | Y32: =W32*X32 -> 11400 | Z32: 18 | AA32: 6 | AB32: =Z32*AA32 -> 108 | AC32: =H32+K32+N32+Q32+T32+W32+Z32 -> 216 | AD32: =J32+M32+P32+S32+V32+Y32+AB32 -> 90108 | AF32: 18
A33: 13 | B33: Краевой турнир по волейболу среди среди сильнейших команд ветеранов | C33: КС | D33: мужчины 40 лет и старше, женщины 35 лет и старше | E33: февраль | F33: февраль | G33: п. Ольгинка (Туапсинский район) | H33: 6 | I33: 3400 | J33: =H33*I33 -> 20400 | K33: 6 | L33: 3000 | M33: =K33*L33 -> 18000 | N33: 6 | O33: 2900 | P33: =N33*O33 -> 17400 | Q33: 60 | R33: 190 | S33: =Q33*R33 -> 11400 | T33: 60 | U33: 190 | V33: =T33*U33 -> 11400 | W33: 60 | X33: 190 | Y33: =W33*X33 -> 11400 | Z33: 20 | AA33: 6 | AB33: =Z33*AA33 -> 120 | AC33: =H33+K33+N33+Q33+T33+W33+Z33 -> 218 | AD33: =J33+M33+P33+S33+V33+Y33+AB33 -> 90120 | AF33: 18
A34: 14 | B34: Краевые соревнования по настольному теннису среди ветеранов физической культуры и спорта Кубани памяти МС МК ЗТР Г.М. Стрельникова | C34: КС | D34: мужчины 40-70+ лет, женщины 40-55+ лет | E34: март | F34: март | G34: согласно положению | Q34: 8 | R34: 190 | S34: =Q34*R34 -> 1520 | T34: 8 | U34: 190 | V34: =T34*U34 -> 1520 | W34: 16 | X34: 190 | Y34: =W34*X34 -> 3040 | Z34: 32 | AA34: 6 | AB34: =Z34*AA34 -> 192 | AC34: =H34+K34+N34+Q34+T34+W34+Z34 -> 64 | AD34: =J34+M34+P34+S34+V34+Y34+AB34 -> 6272 | AF34: 32
A35: 15 | B35: Краевой турнир по футболу среди смешанных детских команд (девочки и мальчики до 12 лет) I этап (региональный) | C35: КС | D35: девочки и мальчики до 12 лет | E35: 46113 | F35: 46142 | G35: г. Краснодар | H35: 1 | I35: 3400 | J35: =H35*I35 -> 3400 | K35: 1 | L35: 3000 | M35: =K35*L35 -> 3000 | N35: 1 | O35: 2900 | P35: =N35*O35 -> 2900 | Q35: 13 | R35: 190 | S35: =Q35*R35 -> 2470 | T35: 13 | U35: 190 | V35: =T35*U35 -> 2470 | W35: 13 | X35: 190 | Y35: =W35*X35 -> 2470 | Z35: 48 | AA35: 6 | AB35: =Z35*AA35 -> 288 | AC35: =H35+K35+N35+Q35+T35+W35+Z35 -> 90 | AD35: =J35+M35+P35+S35+V35+Y35+AB35 -> 16998 | AF35: 47
A36: 16 | B36: Краевой турнир по футболу "Кожаный мяч - Лига юных футболистов" II этап (региональный) | C36: КТ | D36: девочки и мальчики до 12, до 14 лет и до 16 лет, мальчики до 18 лет | E36: 46119 | F36: 46203 | G36: города и районы Краснодарского края, г. Краснодар | H36: 10 | I36: 3400 | J36: =H36*I36 -> 34000 | K36: 10 | L36: 3000 | M36: =K36*L36 -> 30000 | N36: 10 | O36: 2900 | P36: =N36*O36 -> 29000 | Q36: 143 | R36: 190 | S36: =Q36*R36 -> 27170 | T36: 143 | U36: 190 | V36: =T36*U36 -> 27170 | W36: 143 | X36: 190 | Y36: =W36*X36 -> 27170 | Z36: 520 | AA36: 6 | AB36: =Z36*AA36 -> 3120 | AC36: =H36+K36+N36+Q36+T36+W36+AA36 -> 465 | AD36: =J36+M36+P36+S36+V36+Y36+AB36 -> 177630 | AF36: 519
A37: 17 | B37: Краевой турнир по футболу "Кожаный мяч - детям" I этап (региональный) | C37: КТ | D37: мальчики до 10 лет | E37: 46266 | F37: 46295 | G37: г. Краснодар | H37: 1 | I37: 3400 | J37: =H37*I37 -> 3400 | K37: 1 | L37: 3000 | M37: =K37*L37 -> 3000 | N37: 1 | O37: 2900 | P37: =N37*O37 -> 2900 | Q37: 11 | R37: 190 | S37: =Q37*R37 -> 2090 | T37: 11 | U37: 190 | V37: =T37*U37 -> 2090 | W37: 11 | X37: 190 | Y37: =W37*X37 -> 2090 | Z37: 42 | AA37: 6 | AB37: =Z37*AA37 -> 252 | AC37: =H37+K37+N37+Q37+T37+W37+AA37 -> 42 | AD37: =J37+M37+P37+S37+V37+Y37+AB37 -> 15822 | AF37: 519
A38: 18 | B38: Физкультурное мероприятие по футболу среди мальчиков до 10 лет. Предварительный этап Финальный этап. | C38: КТ | D38: мальчики до 10 лет 2017г.р. | E38: 24.04.2026 23.05.2026 | F38: 17.05.2026 27.05.2026 | G38: п. Новомихайловский Туапсинский р-н | H38: 1 | I38: 3400 | J38: =H38*I38 -> 3400 | K38: 1 | L38: 3000 | M38: =K38*L38 -> 3000 | N38: 1 | O38: 2900 | P38: =N38*O38 -> 2900 | Q38: 15 | R38: 190 | S38: =Q38*R38 -> 2850 | T38: 15 | U38: 190 | V38: =T38*U38 -> 2850 | W38: 15 | X38: 190 | Y38: =W38*X38 -> 2850 | Z38: 53 | AA38: 6 | AB38: =Z38*AA38 -> 318 | AC38: =H38+K38+N38+Q38+T38+W38+Z38 -> 101 | AD38: =J38+M38+P38+S38+V38+Y38+AB38 -> 18168
A39: 19 | B39: Краевой турнир по футболу среди смешанных детских команд (девочки и мальчики до 10 лет) I этап (региональный) | C39: КС | D39: девочки и мальчики до 10 лет | E39: 46113 | F39: 46142 | G39: г. Краснодар | H39: 1 | I39: 3400 | J39: =H39*I39 -> 3400 | K39: 1 | L39: 3000 | M39: =K39*L39 -> 3000 | N39: 1 | O39: 2900 | P39: =N39*O39 -> 2900 | Q39: 11 | R39: 190 | S39: =Q39*R39 -> 2090 | T39: 11 | U39: 190 | V39: =T39*U39 -> 2090 | W39: 11 | X39: 190 | Y39: =W39*X39 -> 2090 | Z39: 42 | AA39: 6 | AB39: =Z39*AA39 -> 252 | AC39: =H39+K39+N39+Q39+T39+W39+Z39 -> 78 | AD39: =J39+M39+P39+S39+V39+Y39+AB39 -> 15822 | AF39: 41
A40: 20 | B40: Краевые семейные спортивные игры «Стартуем вместе» I этап, II этап | C40: КС | D40: согласно положению | E40: февраль | F40: июнь | G40: муниципальные образования Краснодарского края, г. Славянск-на -Кубани | H40: 2 | I40: 3400 | J40: =H40*I40 -> 6800 | K40: 2 | L40: 3000 | M40: =K40*L40 -> 6000 | N40: 2 | O40: 2900 | P40: =N40*O40 -> 5800 | Q40: 26 | R40: 190 | S40: =Q40*R40 -> 4940 | T40: 26 | U40: 190 | V40: =T40*U40 -> 4940 | W40: 26 | X40: 190 | Y40: =W40*X40 -> 4940 | Z40: 36 | AA40: 6 | AB40: =Z40*AA40 -> 216 | AC40: =H40+K40+N40+Q40+T40+W40+Z40 -> 120 | AD40: =J40+M40+P40+S40+V40+Y40+AB40 -> 33636
A41: 21 | B41: Спартакиада пенсионеров Краснодарского края 2026 года | C41: КС | D41: мужчины (60 лет и старше), женщины (55 лет и старше) | E41: май | F41: май | G41: г. Краснодар | H41: 1 | I41: 3400 | J41: =H41*I41 -> 3400 | K41: 1 | L41: 3000 | M41: =K41*L41 -> 3000 | N41: 1 | O41: 2900 | P41: =N41*O41 -> 2900 | Q41: 16 | R41: 190 | S41: =Q41*R41 -> 3040 | T41: 16 | U41: 190 | V41: =T41*U41 -> 3040 | W41: 16 | X41: 190 | Y41: =W41*X41 -> 3040 | Z41: 51 | AA41: 6 | AB41: =Z41*AA41 -> 306 | AC41: =H41+K41+N41+Q41+T41+W41+Z41 -> 102 | AD41: =J41+M41+P41+S41+V41+Y41+AB41 -> 18726
...

Sheet Приложение 2
AC1: УТВЕРЖДАЮ
AC2: Руководитель государственного бюджетного учреждения Краснодарского края "Центр развития спорта"
AC3: _______________ В.П. Колпаков
AC4: "____" __________ 20__ г.
H5: Приложение 2
G6: УТВЕРЖДАЮ Руководитель ГБУ КК "Центр развития спорта" ________________ В.П. Колпаков "_____" ____________ 20____ г. согласно приказу
A11: Календарный план официальных физкультурных и спортивных мероприятий государственного бюджетного учреждения Краснодарского края "Центр развития спорта" на 2026 год в части обеспечения наградной атрибутикой за счет субсидий на финансовое обеспечение выполнения государственного задания на оказание государственных услуг (выполнение работ) прошлых лет.
A14: № п/п | B14: Ответственный за проведение мероприятия | C14: Вид спорта | D14: Наименование мероприятия | E14: Вид соревнований | F14: Возраст | G14: Дата проведения (начало мероприятия) | H14: Дата проведения (конец мероприятия) | I14: Место проведения | J14: Количество кубков | S14: Количество медалей | AB14: Грамоты | AE14: Услуги по изготовлению и поставке | AG14: Всего по виду спорта
J15: 1 место Кол-во, шт. | K15: Стоимость 1 шт. | L15: Итого | M15: 2 место Кол-во, шт. | N15: Стоимость 1 шт. | O15: Итого | P15: 3 место Кол-во, шт. | Q15: Стоимость 1 шт. | R15: Итого | S15: 1 место Кол-во, шт. | T15: Стоимость 1 шт. | U15: Итого | V15: 2 место Кол-во, шт. | W15: Стоимость 1 шт. | X15: Итого | Y15: 3 место Количество, шт. | Z15: Стоимость 1 | AA15: Итого | AB15: Кол-во, шт. | AC15: Стоимость 1 шт. | AD15: Итого | AE15: Кол-во ед наградного материала | AF15: Сумма
D16: ФИЗКУЛЬТУРНЫЕ МЕРОПРИЯТИЯ СРЕДИ РАЗЛИЧНЫХ ВОЗРАСТНЫХ ГРУПП НАСЕЛЕНИЯ И ИНВАЛИДОВ
D17: ФИЗКУЛЬТУРНЫЕ МЕРОПРИЯТИЯ
D20: ГОТОВ К ТРУДУ И ОБОРОНЕ
D70: КОНЬКОБЕЖНЫЙ СПОРТ
D72: КИОКУШИН
D75: КИКБОКСИНГ
A78: КОМПЬЮТЕРНЫЙ СПОРТ
D81: КЕРЛИНГ
D83: ЛАПТА
D86: ЛЕГКАЯ АТЛЕТИКА
D93: НАСТОЛЬНЫЙ ТЕННИС
D96: ПРЫЖКИ НА БАТУТЕ
AH98: положение 18.12.2025
AH99: положение 18.12.2025
D101: ПРЫЖКИ В ВОДУ
D103: ПОДВОДНЫЙ СПОРТ
D106: ПУЛЕВАЯ СТРЕЛЬБА
D109: ПОЛИАТЛОН
D110: ПЛАВАНИЕ
A115: РЕГБИ
D117: РУКОПАШНЫЙ БОЙ
A119: РАДИОСПОРТ
D126: СНОУБОРД
D127: СЁРФИНГ
D130: СПОРТИВНОЕ ПРОГРАММИРОВАНИЕ
D132: СПОРТИВНАЯ АКРОБАТИКА
D135: СПОРТИВНЫЙ ТУРИЗМ
D144: СИНХРОННОЕ ПЛАВАНИЕ
D147: СПОРТИВНАЯ ГИМНАСТИКА
A155: САМБО
D157: СТЕНДОВАЯ СТРЕЛЬБА
...

Sheet Приложение 3
AC1: УТВЕРЖДАЮ
AC2: Руководитель государственного бюджетного учреждения Краснодарского края "Центр развития спорта"
AC3: _______________ В.П. Колпаков
AC4: "____" __________ 20__ г.
H5: Приложение 3 | AC5: УТВЕРЖДАЮ
G6: УТВЕРЖДАЮ Руководитель ГБУ КК "Центр развития спорта" ________________ В.П. Колпаков "_____" ____________ 20____ г. согласно приказу № _____ от "____" ______ 20____ г. | AC6: руководитель ГБУ КК "Центр развития спорта"
AC7: _________________ В.П. Колпаков
A11: Календарный план официальных физкультурных и спортивных мероприятий государственного бюджетного учреждения Краснодарского края "Центр развития спорта" на 2026 год в части обеспечения наградной атрибутикой за счет субсидий на финансовое обеспечение выполнения государственного задания на оказание государственных услуг (выполнение работ), дополнительно.
A14: № п/п | B14: Ответственный за проведение мероприятия | C14: Вид спорта | D14: Наименование мероприятия | E14: Вид соревнований | F14: Возраст | G14: Дата проведения (начало мероприятия) | H14: Дата проведения (конец мероприятия) | I14: Место проведения | J14: Количество кубков | S14: Количество медалей | AB14: Грамоты | AE14: Услуги по изготовлению и поставке | AG14: Всего по виду спорта
J15: 1 место Кол-во, шт. | K15: Стоимость 1 шт. | L15: Итого | M15: 2 место Кол-во, шт. | N15: Стоимость 1 шт. | O15: Итого | P15: 3 место Кол-во, шт. | Q15: Стоимость 1 шт. | R15: Итого | S15: 1 место Кол-во, шт. | T15: Стоимость 1 шт. | U15: Итого | V15: 2 место Кол-во, шт. | W15: Стоимость 1 шт. | X15: Итого | Y15: 3 место Количество, шт. | Z15: Стоимость 1 | AA15: Итого | AB15: Кол-во, шт. | AC15: Стоимость 1 шт. | AD15: Итого | AE15: Кол-во ед наградного материала | AF15: Сумма
D16: ФИЗКУЛЬТУРНЫЕ МЕРОПРИЯТИЯ СРЕДИ РАЗЛИЧНЫХ ВОЗРАСТНЫХ ГРУПП НАСЕЛЕНИЯ И ИНВАЛИДОВ
D17: ФИЗКУЛЬТУРНЫЕ МЕРОПРИЯТИЯ
A20: АЛЬПИНИЗМ
D23: БОУЛИНГ
A26: ГАНДБОЛ
D29: КИОКУШИН
A30: КИКБОКСИНГ
D77: УШУ
D79: ФЕХТОВАНИЕ
D82: ИТОГО | AF82: 1766622
A83: Заместитель руководителя | I83: Р.Ю.Александров
A84: Начальник отдела по взаимодействию с физкультурно-спортивными организациями
I85: Э.С.Гильгенберг

Sheet ДИНАМО 
A3: Краснодарская краевая организация Общества «Динамо»
D5: № п/п | E5: Учреждение/ Федерация | F5: Вид спорта | G5: Наименование мероприятия (полное) с учетом вида спорта | H5: Возраст спортсменов в соответствии с ЕВСК | I5: Дата проведения (начало мероприятия) | J5: Дата проведения (конец мероприятия) | K5: Место проведения | L5: Кол-во кубков (командный зачет) | O5: Кол-во медалей | R5: Кол-во грамот | S5: Количество кубков | AB5: Количество медалей | AK5: Грамоты | AN5: Услуги по изготовлению и поставке
L6: 1 | M6: 2 | N6: 3 | O6: 1 | P6: 2 | Q6: 3 | S6: 1 место Кол-во, шт. | T6: Стоимость 1 шт. | U6: Итого | V6: 2 место Кол-во, шт. | W6: Стоимость 1 шт. | X6: Итого | Y6: 3 место Кол-во, шт. | Z6: Стоимость 1 шт. | AA6: Итого | AB6: 1 место Кол-во, шт. | AC6: Стоимость 1 шт. | AD6: Итого | AE6: 2 место Кол-во, шт. | AF6: Стоимость 1 шт. | AG6: Итого | AH6: 3 место Количество, шт. | AI6: Стоимость 1 | AJ6: Итого | AK6: Кол-во, шт. | AL6: Стоимость 1 шт. | AM6: Итого | AN6: Кол-во ед наградного материала | AO6: Сумма
D7: 1 | E7: Краснодарская краевая организация Общества «Динамо» | F7: Стрельба из боевого ручного стрелкового оружия | G7: 68-я Спартакиада Краснодарской краевой организации Общества «Динамо» | H7: 21-50 лет | I7: по назначению | J7: по назначению | K7: г.Краснодар | L7: 3 | M7: 3 | N7: 3 | O7: 13 | P7: 13 | Q7: 13 | R7: - | S7: 3 | T7: 3400 | U7: =S7*T7 -> 10200 | V7: 3 | W7: 3000 | X7: =V7*W7 -> 9000 | Y7: 3 | Z7: 2900 | AA7: =Y7*Z7 -> 8700 | AB7: 13 | AC7: 190 | AD7: =AB7*AC7 -> 2470 | AE7: 13 | AF7: 190 | AG7: =AE7*AF7 -> 2470 | AH7: 13 | AI7: 190 | AJ7: =AH7*AI7 -> 2470 | AN7: =S7+V7+Y7+AB7+AE7+AH7+AK7 -> 48 | AO7: =U7+X7+AA7+AD7+AG7+AJ7+AM7 -> 35310
F8: Плавание | G8: 68-я Спартакиада Краснодарской краевой организации Общества «Динамо» | H8: 21- 50 лет | I8: по назначению | J8: по назначению | K8: г.Краснодар | L8: 3 | M8: 3 | N8: 3 | O8: 12 | P8: 12 | Q8: 12 | R8: - | S8: 3 | T8: 3400 | U8: =S8*T8 -> 10200 | V8: 3 | W8: 3000 | X8: =V8*W8 -> 9000 | Y8: 3 | Z8: 2900 | AA8: =Y8*Z8 -> 8700 | AB8: 12 | AC8: 190 | AD8: =AB8*AC8 -> 2280 | AE8: 12 | AF8: 190 | AG8: =AE8*AF8 -> 2280 | AH8: 12 | AI8: 190 | AJ8: =AH8*AI8 -> 2280 | AN8: =S8+V8+Y8+AB8+AE8+AH8+AK8 -> 45 | AO8: =U8+X8+AA8+AD8+AG8+AJ8+AM8 -> 34740
F9: Мини-футбол | G9: 68-я Спартакиада Краснодарской краевой организации Общества «Динамо» | H9: 21-50 лет | I9: по назначению | J9: по назначению | K9: г.Краснодар | L9: 3 | M9: 3 | N9: 3 | O9: 36 | P9: 36 | Q9: 36 | R9: - | S9: 3 | T9: 3400 | U9: =S9*T9 -> 10200 | V9: 3 | W9: 3000 | X9: =V9*W9 -> 9000 | Y9: 3 | Z9: 2900 | AA9: =Y9*Z9 -> 8700 | AB9: 36 | AC9: 190 | AD9: =AB9*AC9 -> 6840 | AE9: 36 | AF9: 190 | AG9: =AE9*AF9 -> 6840 | AH9: 36 | AI9: 190 | AJ9: =AH9*AI9 -> 6840 | AN9: =S9+V9+Y9+AB9+AE9+AH9+AK9 -> 117 | AO9: =U9+X9+AA9+AD9+AG9+AJ9+AM9 -> 48420
F10: Легкоатлетическая эстафета 4х400 метров | G10: 68-я Спартакиада Краснодарской краевой организации Общества «Динамо» | H10: 21-50 лет | I10: по назначению | J10: по назначению | K10: г.Краснодар | L10: 3 | M10: 3 | N10: 3 | O10: 12 | P10: 12 | Q10: 12 | R10: - | S10: 3 | T10: 3400 | U10: =S10*T10 -> 10200 | V10: 3 | W10: 3000 | X10: =V10*W10 -> 9000 | Y10: 3 | Z10: 2900 | AA10: =Y10*Z10 -> 8700 | AB10: 12 | AC10: 190 | AD10: =AB10*AC10 -> 2280 | AE10: 12 | AF10: 190 | AG10: =AE10*AF10 -> 2280 | AH10: 12 | AI10: 190 | AJ10: =AH10*AI10 -> 2280 | AN10: =S10+V10+Y10+AB10+AE10+AH10+AK10 -> 45 | AO10: =U10+X10+AA10+AD10+AG10+AJ10+AM10 -> 34740
F11: Легкая атлетика кросс | G11: 68-я Спартакиада Краснодарской краевой организации Общества «Динамо» | H11: 21-50 лет | I11: по назначению | J11: по назначению | K11: г.Краснодар | L11: 3 | M11: 3 | N11: 3 | O11: 13 | P11: 13 | Q11: 13 | R11: - | S11: 3 | T11: 3400 | U11: =S11*T11 -> 10200 | V11: 3 | W11: 3000 | X11: =V11*W11 -> 9000 | Y11: 3 | Z11: 2900 | AA11: =Y11*Z11 -> 8700 | AB11: 13 | AC11: 190 | AD11: =AB11*AC11 -> 2470 | AE11: 13 | AF11: 190 | AG11: =AE11*AF11 -> 2470 | AH11: 13 | AI11: 190 | AJ11: =AH11*AI11 -> 2470 | AN11: =S11+V11+Y11+AB11+AE11+AH11+AK11 -> 48 | AO11: =U11+X11+AA11+AD11+AG11+AJ11+AM11 -> 35310
F12: Волейбол | G12: 68-я Спартакиада Краснодарской краевой организации Общества «Динамо» | H12: 21-50 лет | I12: по назначению | J12: по назначению | K12: г.Краснодар | L12: 3 | M12: 3 | N12: 3 | O12: 36 | P12: 36 | Q12: 36 | R12: - | S12: 3 | T12: 3400 | U12: =S12*T12 -> 10200 | V12: 3 | W12: 3000 | X12: =V12*W12 -> 9000 | Y12: 3 | Z12: 2900 | AA12: =Y12*Z12 -> 8700 | AB12: 36 | AC12: 190 | AD12: =AB12*AC12 -> 6840 | AE12: 36 | AF12: 190 | AG12: =AE12*AF12 -> 6840 | AH12: 36 | AI12: 190 | AJ12: =AH12*AI12 -> 6840 | AN12: =S12+V12+Y12+AB12+AE12+AH12+AK12 -> 117 | AO12: =U12+X12+AA12+AD12+AG12+AJ12+AM12 -> 48420
F13: Служебный биатлон | G13: 68-я Спартакиада Краснодарской краевой организации Общества «Динамо» | H13: 21-50 лет | I13: по назначению | J13: по назначению | K13: г.Краснодар | L13: 3 | M13: 3 | N13: 3 | O13: 16 | P13: 16 | Q13: 16 | R13: - | S13: 3 | T13: 3400 | U13: =S13*T13 -> 10200 | V13: 3 | W13: 3000 | X13: =V13*W13 -> 9000 | Y13: 3 | Z13: 2900 | AA13: =Y13*Z13 -> 8700 | AB13: 16 | AC13: 190 | AD13: =AB13*AC13 -> 3040 | AE13: 16 | AF13: 190 | AG13: =AE13*AF13 -> 3040 | AH13: 16 | AI13: 190 | AJ13: =AH13*AI13 -> 3040 | AN13: =S13+V13+Y13+AB13+AE13+AH13+AK13 -> 57 | AO13: =U13+X13+AA13+AD13+AG13+AJ13+AM13 -> 37020
F14: Полоса препятствий | G14: 68-я Спартакиада Краснодарской краевой организации Общества «Динамо» | H14: 21-50 лет | I14: по назначению | J14: по назначению | K14: г.Краснодар | L14: 3 | M14: 3 | N14: 3 | O14: 13 | P14: 13 | Q14: 13 | R14: - | S14: 3 | T14: 3400 | U14: =S14*T14 -> 10200 | V14: 3 | W14: 3000 | X14: =V14*W14 -> 9000 | Y14: 3 | Z14: 2900 | AA14: =Y14*Z14 -> 8700 | AB14: 13 | AC14: 190 | AD14: =AB14*AC14 -> 2470 | AE14: 13 | AF14: 190 | AG14: =AE14*AF14 -> 2470 | AH14: 13 | AI14: 190 | AJ14: =AH14*AI14 -> 2470 | AN14: =S14+V14+Y14+AB14+AE14+AH14+AK14 -> 48 | AO14: =U14+X14+AA14+AD14+AG14+AJ14+AM14 -> 35310
F15: Общекомандное первенство | G15: 68-я Спартакиада Краснодарской краевой организации Общества «Динамо» | H15: 21-50 лет | I15: по назначению | J15: по назначению | K15: г.Краснодар | L15: 3 | M15: 3 | N15: 3 | O15: 13 | P15: 13 | Q15: 13 | R15: - | S15: 3 | T15: 3400 | U15: =S15*T15 -> 10200 | V15: 3 | W15: 3000 | X15: =V15*W15 -> 9000 | Y15: 3 | Z15: 2900 | AA15: =Y15*Z15 -> 8700
K16: ИТОГО | S16: 27 | V16: 27 | Y16: 27 | AB16: =SUM(AB7:AB14) -> 151 | AE16: =SUM(AE7:AE14) -> 151 | AH16: =SUM(AH7:AH14) -> 151
F17: Стрельба из боевого ручного стрелкового оружия | G17: Спартакиада Краснодарской краевой организации Общества «Динамо» совместно с Новороссийской городской организацией Общества "Динамо" | H17: 21-50 лет | I17: по назначению | J17: по назначению | K17: г.Новороссийск | L17: 2 | M17: 2 | N17: 2 | O17: 7 | P17: 7 | Q17: 7 | R17: - | S17: 2 | T17: 3400 | U17: =S17*T17 -> 6800 | V17: 2 | W17: 3000 | X17: =V17*W17 -> 6000 | Y17: 2 | Z17: 2900 | AA17: =Y17*Z17 -> 5800 | AB17: 7 | AC17: 190 | AD17: =AB17*AC17 -> 1330 | AE17: 7 | AF17: 190 | AG17: =AE17*AF17 -> 1330 | AH17: 7 | AI17: 190 | AJ17: =AH17*AI17 -> 1330 | AN17: =S17+V17+Y17+AB17+AE17+AH17+AK17 -> 27 | AO17: =U17+X17+AA17+AD17+AG17+AJ17+AM17 -> 22590
F18: Плавание | G18: Спартакиада Краснодарской краевой организации Общества «Динамо» совместно с Новороссийской городской организацией Общества "Динамо" | H18: 21-50 лет | I18: по назначению | J18: по назначению | K18: г.Новороссийск | L18: 2 | M18: 2 | N18: 2 | O18: 9 | P18: 9 | Q18: 9 | R18: - | S18: 2 | T18: 3400 | U18: =S18*T18 -> 6800 | V18: 2 | W18: 3000 | X18: =V18*W18 -> 6000 | Y18: 2 | Z18: 2900 | AA18: =Y18*Z18 -> 5800 | AB18: 9 | AC18: 190 | AD18: =AB18*AC18 -> 1710 | AE18: 9 | AF18: 190 | AG18: =AE18*AF18 -> 1710 | AH18: 9 | AI18: 190 | AJ18: =AH18*AI18 -> 1710 | AN18: =S18+V18+Y18+AB18+AE18+AH18+AK18 -> 33 | AO18: =U18+X18+AA18+AD18+AG18+AJ18+AM18 -> 23730
F19: Армспорт | G19: Спартакиада Краснодарской краевой организации Общества «Динамо» совместно с Новороссийской городской организацией Общества "Динамо" | H19: 21-50 лет | I19: по назначению | J19: по назначению | K19: г.Новороссийск | L19: 2 | M19: 2 | N19: 2 | O19: 9 | P19: 9 | Q19: 9 | R19: - | S19: 2 | T19: 3400 | U19: =S19*T19 -> 6800 | V19: 2 | W19: 3000 | X19: =V19*W19 -> 6000 | Y19: 2 | Z19: 2900 | AA19: =Y19*Z19 -> 5800 | AB19: 9 | AC19: 190 | AD19: =AB19*AC19 -> 1710 | AE19: 9 | AF19: 190 | AG19: =AE19*AF19 -> 1710 | AH19: 9 | AI19: 190 | AJ19: =AH19*AI19 -> 1710 | AN19: =S19+V19+Y19+AB19+AE19+AH19+AK19 -> 33 | AO19: =U19+X19+AA19+AD19+AG19+AJ19+AM19 -> 23730
F20: Гиревой спорт | G20: Спартакиада Краснодарской краевой организации Общества «Динамо» совместно с Новороссийской городской организацией Общества "Динамо" | H20: 21-50 лет | I20: по назначению | J20: по назначению | K20: г.Новороссийск | L20: 2 | M20: 2 | N20: 2 | O20: 9 | P20: 9 | Q20: 9 | R20: - | S20: 2 | T20: 3400 | U20: =S20*T20 -> 6800 | V20: 2 | W20: 3000 | X20: =V20*W20 -> 6000 | Y20: 2 | Z20: 2900 | AA20: =Y20*Z20 -> 5800 | AB20: 9 | AC20: 190 | AD20: =AB20*AC20 -> 1710 | AE20: 9 | AF20: 190 | AG20: =AE20*AF20 -> 1710 | AH20: 9 | AI20: 190 | AJ20: =AH20*AI20 -> 1710 | AN20: =S20+V20+Y20+AB20+AE20+AH20+AK20 -> 33 | AO20: =U20+X20+AA20+AD20+AG20+AJ20+AM20 -> 23730
F21: Легкоатлетическая эстафета 4х400 метров, бег 1500 и 3000 метров | G21: Спартакиада Краснодарской краевой организации Общества «Динамо» совместно с Новороссийской городской организацией Общества "Динамо" | H21: 21-50 лет | I21: по назначению | J21: по назначению | K21: г.Новороссийск | L21: 2 | M21: 2 | N21: 2 | O21: 10 | P21: 10 | Q21: 10 | R21: - | S21: 2 | T21: 3400 | U21: =S21*T21 -> 6800 | V21: 2 | W21: 3000 | X21: =V21*W21 -> 6000 | Y21: 2 | Z21: 2900 | AA21: =Y21*Z21 -> 5800 | AB21: 10 | AC21: 190 | AD21: =AB21*AC21 -> 1900 | AE21: 10 | AF21: 190 | AG21: =AE21*AF21 -> 1900 | AH21: 10 | AI21: 190 | AJ21: =AH21*AI21 -> 1900 | AN21: =S21+V21+Y21+AB21+AE21+AH21+AK21 -> 36 | AO21: =U21+X21+AA21+AD21+AG21+AJ21+AM21 -> 24300
F22: Мини-футбол | G22: Спартакиада Краснодарской краевой организации Общества «Динамо» совместно с Новороссийской городской организацией Общества "Динамо" | H22: 21-50 лет | I22: по назначению | J22: по назначению | K22: г.Новороссийск | L22: 2 | M22: 2 | N22: 2 | O22: 20 | P22: 20 | Q22: 20 | R22: - | S22: 2 | T22: 3400 | U22: =S22*T22 -> 6800 | V22: 2 | W22: 3000 | X22: =V22*W22 -> 6000 | Y22: 2 | Z22: 2900 | AA22: =Y22*Z22 -> 5800 | AB22: 20 | AC22: 190 | AD22: =AB22*AC22 -> 3800 | AE22: 20 | AF22: 190 | AG22: =AE22*AF22 -> 3800 | AH22: 20 | AI22: 190 | AJ22: =AH22*AI22 -> 3800 | AN22: =S22+V22+Y22+AB22+AE22+AH22+AK22 -> 66 | AO22: =U22+X22+AA22+AD22+AG22+AJ22+AM22 -> 30000
F23: Пляжный волейбол | G23: Спартакиада Краснодарской краевой организации Общества «Динамо» совместно с Новороссийской городской организацией Общества "Динамо" | H23: 21-50 лет | I23: по назначению | J23: по назначению | K23: г.Новороссийск | L23: 2 | M23: 2 | N23: 2 | O23: 4 | P23: 4 | Q23: 4 | R23: - | S23: 2 | T23: 3400 | U23: =S23*T23 -> 6800 | V23: 2 | W23: 3000 | X23: =V23*W23 -> 6000 | Y23: 2 | Z23: 2900 | AA23: =Y23*Z23 -> 5800 | AB23: 4 | AC23: 190 | AD23: =AB23*AC23 -> 760 | AE23: 4 | AF23: 190 | AG23: =AE23*AF23 -> 760 | AH23: 4 | AI23: 190 | AJ23: =AH23*AI23 -> 760 | AN23: =S23+V23+Y23+AB23+AE23+AH23+AK23 -> 18 | AO23: =U23+X23+AA23+AD23+AG23+AJ23+AM23 -> 20880
F24: Шахматы | G24: Спартакиада Краснодарской краевой организации Общества «Динамо» совместно с Новороссийской городской организацией Общества "Динамо" | H24: 21-50 лет | I24: по назначению | J24: по назначению | K24: г.Новороссийск | L24: 2 | M24: 2 | N24: 2 | O24: 4 | P24: 4 | Q24: 4 | R24: - | S24: 2 | T24: 3400 | U24: =S24*T24 -> 6800 | V24: 2 | W24: 3000 | X24: =V24*W24 -> 6000 | Y24: 2 | Z24: 2900 | AA24: =Y24*Z24 -> 5800 | AB24: 4 | AC24: 190 | AD24: =AB24*AC24 -> 760 | AE24: 4 | AF24: 190 | AG24: =AE24*AF24 -> 760 | AH24: 4 | AI24: 190 | AJ24: =AH24*AI24 -> 760 | AN24: =S24+V24+Y24+AB24+AE24+AH24+AK24 -> 18 | AO24: =U24+X24+AA24+AD24+AG24+AJ24+AM24 -> 20880
F25: Настольный теннис | G25: Спартакиада Краснодарской краевой организации Общества «Динамо» совместно с Новороссийской городской организацией Общества "Динамо" | H25: 21-50 лет | I25: по назначению | J25: по назначению | K25: г.Новороссийск | L25: 2 | M25: 2 | N25: 2 | O25: 5 | P25: 5 | Q25: 5 | R25: - | S25: 2 | T25: 3400 | U25: =S25*T25 -> 6800 | V25: 2 | W25: 3000 | X25: =V25*W25 -> 6000 | Y25: 2 | Z25: 2900 | AA25: =Y25*Z25 -> 5800 | AB25: 5 | AC25: 190 | AD25: =AB25*AC25 -> 950 | AE25: 5 | AF25: 190 | AG25: =AE25*AF25 -> 950 | AH25: 5 | AI25: 190 | AJ25: =AH25*AI25 -> 950 | AN25: =S25+V25+Y25+AB25+AE25+AH25+AK25 -> 21 | AO25: =U25+X25+AA25+AD25+AG25+AJ25+AM25 -> 21450
F26: Перетягивание каната | G26: Спартакиада Краснодарской краевой организации Общества «Динамо» совместно с Новороссийской городской организацией Общества "Динамо" | H26: 21-50 лет | I26: по назначению | J26: по назначению | K26: г.Новороссийск | L26: 2 | M26: 2 | N26: 2 | O26: 10 | P26: 10 | Q26: 10 | R26: - | S26: 2 | T26: 3400 | U26: =S26*T26 -> 6800 | V26: 2 | W26: 3000 | X26: =V26*W26 -> 6000 | Y26: 2 | Z26: 2900 | AA26: =Y26*Z26 -> 5800 | AB26: 10 | AC26: 190 | AD26: =AB26*AC26 -> 1900 | AE26: 10 | AF26: 190 | AG26: =AE26*AF26 -> 1900 | AH26: 10 | AI26: 190 | AJ26: =AH26*AI26 -> 1900 | AN26: =S26+V26+Y26+AB26+AE26+AH26+AK26 -> 36 | AO26: =U26+X26+AA26+AD26+AG26+AJ26+AM26 -> 24300
F27: Стрельба из пневматической винтовки | G27: Спартакиада Краснодарской краевой организации Общества «Динамо» совместно с Новороссийской городской организацией Общества "Динамо" | H27: 21-50 лет | I27: по назначению | J27: по назначению | K27: г.Новороссийск | L27: 2 | M27: 2 | N27: 2 | O27: 5 | P27: 5 | Q27: 5 | R27: - | S27: 2 | T27: 3400 | U27: =S27*T27 -> 6800 | V27: 2 | W27: 3000 | X27: =V27*W27 -> 6000 | Y27: 2 | Z27: 2900 | AA27: =Y27*Z27 -> 5800 | AB27: 5 | AC27: 190 | AD27: =AB27*AC27 -> 950 | AE27: 5 | AF27: 190 | AG27: =AE27*AF27 -> 950 | AH27: 5 | AI27: 190 | AJ27: =AH27*AI27 -> 950 | AN27: =S27+V27+Y27+AB27+AE27+AH27+AK27 -> 21 | AO27: =U27+X27+AA27+AD27+AG27+AJ27+AM27 -> 21450
F28: Общекомандное первенство | G28: Спартакиада Краснодарской краевой организации Общества «Динамо» совместно с Новороссийской городской организацией Общества "Динамо" | H28: 21-50 лет | I28: по назначению | J28: по назначению | K28: г.Новороссийск | L28: 2 | M28: 2 | N28: 2 | O28: 5 | P28: 5 | Q28: 5 | R28: - | S28: 2 | T28: 3400 | U28: =S28*T28 -> 6800 | V28: 2 | W28: 3000 | X28: =V28*W28 -> 6000 | Y28: 2 | Z28: 2900 | AA28: =Y28*Z28 -> 5800
K29: ИТОГО | S29: 24 | V29: 24 | Y29: 24 | AB29: =SUM(AB17:AB27) -> 92 | AE29: 92 | AH29: 92
F30: Стрельба из пневматического пистолета | G30: 8-я Спартакиада Краснодарской краевой организации Общества «Динамо» среди ветеранов-пенсионеров органов безопасности и правопорядка | H30: 45+ | I30: март | J30: март | K30: г. Краснодар | L30: 1 | M30: 1 | N30: 1 | O30: 5 | P30: 5 | Q30: 5 | R30: - | S30: 1 | T30: 3400 | U30: =S30*T30 -> 3400 | V30: 1 | W30: 3000 | X30: =V30*W30 -> 3000 | Y30: 1 | Z30: 2900 | AA30: =Y30*Z30 -> 2900 | AB30: 5 | AC30: 190 | AD30: =AB30*AC30 -> 950 | AE30: 5 | AF30: 190 | AG30: =AE30*AF30 -> 950 | AH30: 5 | AI30: 190 | AJ30: =AH30*AI30 -> 950 | AN30: =S30+V30+Y30+AB30+AE30+AH30+AK30 -> 18 | AO30: =U30+X30+AA30+AD30+AG30+AJ30+AM30 -> 12150
F31: Стрельба из пневматической винтовки | G31: 8-я Спартакиада Краснодарской краевой организации Общества «Динамо» среди ветеранов-пенсионеров органов безопасности и правопорядка | H31: 45+ | I31: март | J31: март | K31: г. Краснодар | L31: 1 | M31: 1 | N31: 1 | O31: 5 | P31: 5 | Q31: 5 | R31: - | S31: 1 | T31: 3400 | U31: =S31*T31 -> 3400 | V31: 1 | W31: 3000 | X31: =V31*W31 -> 3000 | Y31: 1 | Z31: 2900 | AA31: =Y31*Z31 -> 2900 | AB31: 5 | AC31: 190 | AD31: =AB31*AC31 -> 950 | AE31: 5 | AF31: 190 | AG31: =AE31*AF31 -> 950 | AH31: 5 | AI31: 190 | AJ31: =AH31*AI31 -> 950 | AN31: =S31+V31+Y31+AB31+AE31+AH31+AK31 -> 18 | AO31: =U31+X31+AA31+AD31+AG31+AJ31+AM31 -> 12150
F32: Плавание | G32: 8-я Спартакиада Краснодарской краевой организации Общества «Динамо» среди ветеранов-пенсионеров органов безопасности и правопорядка | H32: 45+ | I32: май | J32: май | K32: г. Краснодар | L32: 1 | M32: 1 | N32: 1 | O32: 5 | P32: 5 | Q32: 5 | R32: - | S32: 1 | T32: 3400 | U32: =S32*T32 -> 3400 | V32: 1 | W32: 3000 | X32: =V32*W32 -> 3000 | Y32: 1 | Z32: 2900 | AA32: =Y32*Z32 -> 2900 | AB32: 5 | AC32: 190 | AD32: =AB32*AC32 -> 950 | AE32: 5 | AF32: 190 | AG32: =AE32*AF32 -> 950 | AH32: 5 | AI32: 190 | AJ32: =AH32*AI32 -> 950 | AN32: =S32+V32+Y32+AB32+AE32+AH32+AK32 -> 18 | AO32: =U32+X32+AA32+AD32+AG32+AJ32+AM32 -> 12150
F33: Шахматы (быстрые) | G33: 8-я Спартакиада Краснодарской краевой организации Общества «Динамо» среди ветеранов-пенсионеров органов безопасности и правопорядка | H33: 45+ | I33: сентябрь | J33: сентябрь | K33: г. Краснодар | L33: 1 | M33: 1 | N33: 1 | O33: 4 | P33: 4 | Q33: 4 | R33: - | S33: 1 | T33: 3400 | U33: =S33*T33 -> 3400 | V33: 1 | W33: 3000 | X33: =V33*W33 -> 3000 | Y33: 1 | Z33: 2900 | AA33: =Y33*Z33 -> 2900 | AB33: 4 | AC33: 190 | AD33: =AB33*AC33 -> 760 | AE33: 4 | AF33: 190 | AG33: =AE33*AF33 -> 760 | AH33: 4 | AI33: 190 | AJ33: =AH33*AI33 -> 760 | AN33: =S33+V33+Y33+AB33+AE33+AH33+AK33 -> 15 | AO33: =U33+X33+AA33+AD33+AG33+AJ33+AM33 -> 11580
F34: Настольный теннис | G34: 8-я Спартакиада Краснодарской краевой организации Общества «Динамо» среди ветеранов-пенсионеров органов безопасности и правопорядка | H34: 45+ | I34: октябрь | J34: октябрь | K34: г. Краснодар | L34: 1 | M34: 1 | N34: 1 | O34: 3 | P34: 3 | Q34: 3 | R34: - | S34: 1 | T34: 3400 | U34: =S34*T34 -> 3400 | V34: 1 | W34: 3000 | X34: =V34*W34 -> 3000 | Y34: 1 | Z34: 2900 | AA34: =Y34*Z34 -> 2900 | AB34: 3 | AC34: 190 | AD34: =AB34*AC34 -> 570 | AE34: 3 | AF34: 190 | AG34: =AE34*AF34 -> 570 | AH34: 3 | AI34: 190 | AJ34: =AH34*AI34 -> 570 | AN34: =S34+V34+Y34+AB34+AE34+AH34+AK34 -> 12 | AO34: =U34+X34+AA34+AD34+AG34+AJ34+AM34 -> 11010
F35: Шашки | G35: 8-я Спартакиада Краснодарской краевой организации Общества «Динамо» среди ветеранов-пенсионеров органов безопасности и правопорядка | H35: 45+ | I35: июнь | J35: июнь | K35: г. Краснодар | L35: 1 | M35: 1 | N35: 1 | O35: 4 | P35: 4 | Q35: 4 | R35: - | S35: 1 | T35: 3400 | U35: =S35*T35 -> 3400 | V35: 1 | W35: 3000 | X35: =V35*W35 -> 3000 | Y35: 1 | Z35: 2900 | AA35: =Y35*Z35 -> 2900 | AB35: 4 | AC35: 190 | AD35: =AB35*AC35 -> 760 | AE35: 4 | AF35: 190 | AG35: =AE35*AF35 -> 760 | AH35: 4 | AI35: 190 | AJ35: =AH35*AI35 -> 760 | AN35: =S35+V35+Y35+AB35+AE35+AH35+AK35 -> 15 | AO35: =U35+X35+AA35+AD35+AG35+AJ35+AM35 -> 11580
F36: Дартс | G36: 8-я Спартакиада Краснодарской краевой организации Общества «Динамо» среди ветеранов-пенсионеров органов безопасности и правопорядка | H36: 45+ | I36: февраль | J36: февраль | K36: г. Краснодар | L36: 1 | M36: 1 | N36: 1 | O36: 5 | P36: 5 | Q36: 5 | R36: - | S36: 1 | T36: 3400 | U36: =S36*T36 -> 3400 | V36: 1 | W36: 3000 | X36: =V36*W36 -> 3000 | Y36: 1 | Z36: 2900 | AA36: =Y36*Z36 -> 2900 | AB36: 5 | AC36: 190 | AD36: =AB36*AC36 -> 950 | AE36: 5 | AF36: 190 | AG36: =AE36*AF36 -> 950 | AH36: 5 | AI36: 190 | AJ36: =AH36*AI36 -> 950 | AN36: =S36+V36+Y36+AB36+AE36+AH36+AK36 -> 18 | AO36: =U36+X36+AA36+AD36+AG36+AJ36+AM36 -> 12150
F37: Рукопашный бой | G37: 8-я Спартакиада Краснодарской краевой организации Общества «Динамо» среди ветеранов-пенсионеров органов безопасности и правопорядка | H37: Дети 12-15 лет | I37: Декабрь | J37: Декабрь | K37: г. Краснодар | L37: 1 | M37: 1 | N37: 1 | O37: 9 | P37: 9 | Q37: 9 | R37: - | S37: 1 | T37: 3400 | U37: =S37*T37 -> 3400 | V37: 1 | W37: 3000 | X37: =V37*W37 -> 3000 | Y37: 1 | Z37: 2900 | AA37: =Y37*Z37 -> 2900 | AB37: 9 | AC37: 190 | AD37: =AB37*AC37 -> 1710 | AE37: 9 | AF37: 190 | AG37: =AE37*AF37 -> 1710 | AH37: 9 | AI37: 190 | AJ37: =AH37*AI37 -> 1710 | AN37: =S37+V37+Y37+AB37+AE37+AH37+AK37 -> 30 | AO37: =U37+X37+AA37+AD37+AG37+AJ37+AM37 -> 14430
F38: Общекомандное первенство | G38: Спартакиада Краснодарской краевой организации Общества «Динамо» совместно с Новороссийской городской организацией Общества "Динамо" | H38: 21-50 лет | I38: по назначению | J38: по назначению | K38: г.Новороссийск | L38: 2 | M38: 2 | N38: 2 | O38: 5 | P38: 5 | Q38: 5 | R38: - | S38: 1 | T38: 3400 | U38: =S38*T38 -> 3400 | V38: 1 | W38: 3000 | X38: =V38*W38 -> 3000 | Y38: 1 | Z38: 2900 | AA38: =Y38*Z38 -> 2900
K39: ИТОГО | S39: 9 | V39: 9 | Y39: 9 | AB39: =SUM(AB30:AB37) -> 40 | AE39: =SUM(AE30:AE37) -> 40 | AH39: =SUM(AH30:AH37) -> 40
F40: Дзюдо | G40: Спартакиада Главного управления ФС ВНГ России по Краснодарскому краю | H40: 21-50 лет | I40: 46048 | J40: 46049 | K40: г. Краснодар | L40: 1 | M40: 1 | N40: 1 | O40: 9 | P40: 9 | Q40: 9 | R40: 30 | S40: 1 | T40: 3400 | U40: =S40*T40 -> 3400 | V40: 1 | W40: 3000 | X40: =V40*W40 -> 3000 | Y40: 1 | Z40: 2900 | AA40: =Y40*Z40 -> 2900 | AB40: 9 | AC40: 190 | AD40: =AB40*AC40 -> 1710 | AE40: 9 | AF40: 190 | AG40: =AE40*AF40 -> 1710 | AH40: 9 | AI40: 190 | AJ40: =AH40*AI40 -> 1710 | AK40: 30 | AL40: 6 | AM40: =AK40*AL40 -> 180 | AN40: =S40+V40+Y40+AB40+AE40+AH40+AK40 -> 60 | AO40: =U40+X40+AA40+AD40+AG40+AJ40+AM40 -> 14610
H41: 21-50 лет
F42: Стрельба из боевого ручного стрелкового | G42: Спартакиада Главного управления ФС ВНГ России по Краснодарскому краю | H42: 21-50 лет | I42: 46091 | J42: 46094 | K42: г. Краснодар | L42: 1 | M42: 1 | N42: 1 | O42: 7 | P42: 7 | Q42: 7 | R42: 26 | S42: 1 | T42: 3400 | U42: =S42*T42 -> 3400 | V42: 1 | W42: 3000 | X42: =V42*W42 -> 3000 | Y42: 1 | Z42: 2900 | AA42: =Y42*Z42 -> 2900 | AB42: 7 | AC42: 190 | AD42: =AB42*AC42 -> 1330 | AE42: 7 | AF42: 190 | AG42: =AE42*AF42 -> 1330 | AH42: 7 | AI42: 190 | AJ42: =AH42*AI42 -> 1330 | AK42: 26 | AL42: 6 | AM42: =AK42*AL42 -> 156 | AN42: =S42+V42+Y42+AB42+AE42+AH42+AK42 -> 50 | AO42: =U42+X42+AA42+AD42+AG42+AJ42+AM42 -> 13446
F43: служебно-боевая стрельта | G43: Спартакиада Главного управления ФС ВНГ России по Краснодарскому краю | H43: 21-50 лет | I43: 46091 | J43: 46094 | K43: г. Краснодар
...

Sheet Спартакиада юнош.
D1: XIII летняя Спартакиада учащихся (юношеская) Кубани 2026 года (по видам спорта)
B2: Вид спорта | C2: Месяц | D2: Дата проведения (начало мероприятия) | E2: Дата проведения (конец мероприятия) | F2: Место проведения | G2: Количество кубков | P2: Количество медалей | Y2: Грамоты | AD2: Дата согласования положения
G3: Кол-во, шт. | H3: Стоимость 1 шт. | I3: Итого | J3: Кол-во, шт. | K3: Стоимость 1 шт. | L3: Итого | M3: Кол-во, шт. | N3: Стоимость 1 шт. | O3: Итого | P3: Кол-во, шт. | Q3: Стоимость 1 шт. | R3: Итого | S3: Кол-во, шт. | T3: Стоимость 1 шт. | U3: Итого | V3: Количество, шт. | W3: Стоимость 1 | X3: Итого | Y3: Кол-во, шт. | Z3: Стоимость 1 шт. | AA3: Итого
A4: 1 | B4: Бадминтон | D4: 46093 | E4: 46096 | F4: г.Гулькевичи | G4: 1 | H4: 3400 | I4: =G4*H4 -> 3400 | J4: 1 | K4: 3000 | L4: =J4*K4 -> 3000 | M4: 1 | N4: 2900 | O4: =M4*N4 -> 2900 | P4: 8 | Q4: 190 | R4: =P4*Q4 -> 1520 | S4: 8 | T4: 190 | U4: =S4*T4 -> 1520 | V4: 16 | W4: 190 | X4: =V4*W4 -> 3040 | Y4: 35 | Z4: 6 | AA4: =Y4*Z4 -> 210 | AB4: =G4+J4+M4+P4+S4+V4+Y4 -> 70 | AC4: =I4+L4+O4+R4+U4+X4+234 -> 15614 | AD4: 46002
A5: 2 | B5: Баскетбол (юноши) | D5: 46103 | E5: 46109 | F5: г. Краснодар | G5: 1 | H5: 3400 | I5: =G5*H5 -> 3400 | J5: 1 | K5: 3000 | L5: =J5*K5 -> 3000 | M5: 1 | N5: 2900 | O5: =M5*N5 -> 2900 | P5: 14 | Q5: 190 | R5: =P5*Q5 -> 2660 | S5: 14 | T5: 190 | U5: =S5*T5 -> 2660 | V5: 14 | W5: 190 | X5: =V5*W5 -> 2660 | Y5: 45 | Z5: 6 | AA5: =Y5*Z5 -> 270 | AB5: =G5+J5+M5+P5+S5+V5+Y5 -> 90 | AC5: =I5+L5+O5+R5+U5+X5+234 -> 17514 | AD5: 46002
A6: 3 | B6: Баскетбол (девушки) | D6: 46096 | E6: 46102 | F6: г. Краснодар | G6: 1 | H6: 3400 | I6: =G6*H6 -> 3400 | J6: 1 | K6: 3000 | L6: =J6*K6 -> 3000 | M6: 1 | N6: 2900 | O6: =M6*N6 -> 2900 | P6: 14 | Q6: 190 | R6: =P6*Q6 -> 2660 | S6: 14 | T6: 190 | U6: =S6*T6 -> 2660 | V6: 14 | W6: 190 | X6: =V6*W6 -> 2660 | Y6: 45 | Z6: 6 | AA6: =Y6*Z6 -> 270 | AB6: =G6+J6+M6+P6+S6+V6+Y6 -> 90 | AC6: =I6+L6+O6+R6+U6+X6+234 -> 17514 | AD6: 46002
A7: 4 | B7: Велосипедный спорт (Маунтибайк) | D7: 46092 | E7: 46096 | F7: г.Геленджик, с.Архипо-Осиповка | G7: 1 | H7: 3400 | I7: =G7*H7 -> 3400 | J7: 1 | K7: 3000 | L7: =J7*K7 -> 3000 | M7: 1 | N7: 2900 | O7: =M7*N7 -> 2900 | P7: 6 | Q7: 190 | R7: =P7*Q7 -> 1140 | S7: 6 | T7: 190 | U7: =S7*T7 -> 1140 | V7: 6 | W7: 190 | X7: =V7*W7 -> 1140 | Y7: 21 | Z7: 6 | AA7: =Y7*Z7 -> 126 | AB7: =G7+J7+M7+P7+S7+V7+Y7 -> 42 | AC7: =I7+L7+O7+R7+U7+X7+234 -> 12954 | AD7: 46002
A8: 5 | B8: Велосипедный спорт (дисциплина шоссе) | D8: 46156 | E8: 46160 | F8: ст-ца Брюховецкая | G8: 1 | H8: 3400 | I8: 3400 | J8: 1 | K8: 3000 | L8: 3000 | M8: 1 | N8: 2900 | O8: 2900 | P8: 4 | Q8: 190 | R8: 1140 | S8: 4 | T8: 190 | U8: 1140 | V8: 4 | W8: 190 | X8: 1140 | Y8: 15 | Z8: 6 | AA8: 126 | AB8: 42 | AC8: 12954 | AD8: 46002
A9: 6 | B9: Велосипедный спорт (BMX) | D9: 46156 | E9: 46160 | F9: ст-ца Брюховецкая | G9: 1 | H9: 3400 | I9: 3400 | J9: 1 | K9: 3000 | L9: 3000 | M9: 1 | N9: 2900 | O9: 2900 | P9: 4 | Q9: 190 | R9: 1140 | S9: 4 | T9: 190 | U9: 1140 | V9: 4 | W9: 190 | X9: 1140 | Y9: 15 | Z9: 6 | AA9: 126 | AB9: 42 | AC9: 12954 | AD9: 46002
A10: 7 | B10: Волейбол (девушки) | D10: 46112 | E10: 46117 | F10: Курганинский район, г.Курганинск | G10: 1 | H10: 3400 | I10: =G10*H10 -> 3400 | J10: 1 | K10: 3000 | L10: =J10*K10 -> 3000 | M10: 1 | N10: 2900 | O10: =M10*N10 -> 2900 | P10: 14 | Q10: 190 | R10: =P10*Q10 -> 2660 | S10: 14 | T10: 190 | U10: =S10*T10 -> 2660 | V10: 14 | W10: 190 | X10: =V10*W10 -> 2660 | Y10: 45 | Z10: 6 | AA10: =Y10*Z10 -> 270 | AB10: =G10+J10+M10+P10+S10+V10+Y10 -> 90 | AC10: =I10+L10+O10+R10+U10+X10+234 -> 17514 | AD10: 46002
A11: 8 | B11: Волейбол (юноши) | D11: 46112 | E11: 46117 | F11: Северский район, пгт.Ильский | G11: 1 | H11: 3400 | I11: =G11*H11 -> 3400 | J11: 1 | K11: 3000 | L11: =J11*K11 -> 3000 | M11: 1 | N11: 2900 | O11: =M11*N11 -> 2900 | P11: 14 | Q11: 190 | R11: =P11*Q11 -> 2660 | S11: 14 | T11: 190 | U11: =S11*T11 -> 2660 | V11: 14 | W11: 190 | X11: =V11*W11 -> 2660 | Y11: 45 | Z11: 6 | AA11: =Y11*Z11 -> 270 | AB11: =G11+J11+M11+P11+S11+V11+Y11 -> 90 | AC11: =I11+L11+O11+R11+U11+X11+234 -> 17514 | AD11: 46002
A12: 9 | B12: Волейбол пляжный | D12: 46146 | E12: 46149 | F12: г.Краснодар | G12: 1 | H12: 3400 | I12: =G12*H12 -> 3400 | J12: 1 | K12: 3000 | L12: =J12*K12 -> 3000 | M12: 1 | N12: 2900 | O12: =M12*N12 -> 2900 | P12: 3 | Q12: 190 | R12: =P12*Q12 -> 570 | S12: 3 | T12: 190 | U12: =S12*T12 -> 570 | V12: 3 | W12: 190 | X12: =V12*W12 -> 570 | Y12: 9 | Z12: 6 | AA12: =Y12*Z12 -> 54 | AB12: =G12+J12+M12+P12+S12+V12+Y12 -> 21 | AC12: =I12+L12+O12+R12+U12+X12+234 -> 11244 | AD12: 46002
A13: 10 | B13: Волейбол пляжный | D13: 46146 | E13: 46149 | F13: г.Краснодар | G13: 1 | H13: 3400 | I13: =G13*H13 -> 3400 | J13: 1 | K13: 3000 | L13: =J13*K13 -> 3000 | M13: 1 | N13: 2900 | O13: =M13*N13 -> 2900 | P13: 3 | Q13: 190 | R13: =P13*Q13 -> 570 | S13: 3 | T13: 190 | U13: =S13*T13 -> 570 | V13: 3 | W13: 190 | X13: =V13*W13 -> 570 | Y13: 9 | Z13: 6 | AA13: =Y13*Z13 -> 54 | AB13: =G13+J13+M13+P13+S13+V13+Y13 -> 21 | AC13: =I13+L13+O13+R13+U13+X13+234 -> 11244 | AD13: 46002
A14: 11 | B14: Гандбол (юноши) | D14: 46048 | E14: 46053 | F14: Павловский район, ст-ца Павловская | G14: 1 | H14: 3400 | I14: =G14*H14 -> 3400 | J14: 1 | K14: 3000 | L14: =J14*K14 -> 3000 | M14: 1 | N14: 2900 | O14: =M14*N14 -> 2900 | P14: 18 | Q14: 190 | R14: =P14*Q14 -> 3420 | S14: 18 | T14: 190 | U14: =S14*T14 -> 3420 | V14: 18 | W14: 190 | X14: =V14*W14 -> 3420 | Y14: 57 | Z14: 6 | AA14: =Y14*Z14 -> 342 | AB14: =G14+J14+M14+P14+S14+V14+Y14 -> 114 | AC14: =I14+L14+O14+R14+U14+X14+234 -> 19794 | AD14: 46002
A15: 12 | B15: Гандбол (девушки) | D15: 46055 | E15: 46060 | F15: Павловский район, ст-ца Павловская | G15: 1 | H15: 3400 | I15: =G15*H15 -> 3400 | J15: 1 | K15: 3000 | L15: =J15*K15 -> 3000 | M15: 1 | N15: 2900 | O15: =M15*N15 -> 2900 | P15: 18 | Q15: 190 | R15: =P15*Q15 -> 3420 | S15: 18 | T15: 190 | U15: =S15*T15 -> 3420 | V15: 18 | W15: 190 | X15: =V15*W15 -> 3420 | Y15: 57 | Z15: 6 | AA15: =Y15*Z15 -> 342 | AB15: =G15+J15+M15+P15+S15+V15+Y15 -> 114 | AC15: =I15+L15+O15+R15+U15+X15+234 -> 19794 | AD15: 46002
A16: 13 | B16: Гребной спорт | C16: пк | D16: 46154 | E16: 46156 | F16: г. Краснодар | G16: 1 | H16: 3400 | I16: =G16*H16 -> 3400 | J16: 1 | K16: 3000 | L16: =J16*K16 -> 3000 | M16: 1 | N16: 2900 | O16: =M16*N16 -> 2900 | P16: 44 | Q16: 190 | R16: =P16*Q16 -> 8360 | S16: 44 | T16: 190 | U16: =S16*T16 -> 8360 | V16: 44 | W16: 190 | X16: =V16*W16 -> 8360 | Y16: 135 | Z16: 6 | AA16: =Y16*Z16 -> 810 | AB16: =G16+J16+M16+P16+S16+V16+Y16 -> 270 | AC16: =I16+L16+O16+R16+U16+X16+234 -> 34614 | AD16: 46002
A17: 14 | B17: ЛАПТА (девушки) | D17: 46200 | E17: 46201 | F17: Кущевский район, ст-ца Кущевская | G17: 1 | H17: 3400 | I17: =G17*H17 -> 3400 | J17: 1 | K17: 3000 | L17: =J17*K17 -> 3000 | M17: 1 | N17: 2900 | O17: =M17*N17 -> 2900 | P17: 8 | Q17: 190 | R17: =P17*Q17 -> 1520 | S17: 8 | T17: 190 | U17: =S17*T17 -> 1520 | V17: 8 | W17: 190 | X17: =V17*W17 -> 1520 | Y17: 24 | Z17: 6 | AA17: =Y17*Z17 -> 144 | AB17: =G17+J17+M17+P17+S17+V17+Y17 -> 51 | AC17: =I17+L17+O17+R17+U17+X17+234 -> 14094 | AD17: 46002 | AG17: нет в потребности
A18: 15 | B18: ЛАПТА (юноши) | D18: 46200 | E18: 46201 | F18: Кущевский район, ст-ца Кущевская | G18: 1 | H18: 3400 | I18: =G18*H18 -> 3400 | J18: 1 | K18: 3000 | L18: =J18*K18 -> 3000 | M18: 1 | N18: 2900 | O18: =M18*N18 -> 2900 | P18: 8 | Q18: 190 | R18: =P18*Q18 -> 1520 | S18: 8 | T18: 190 | U18: =S18*T18 -> 1520 | V18: 8 | W18: 190 | X18: =V18*W18 -> 1520 | Y18: 24 | Z18: 6 | AA18: =Y18*Z18 -> 144 | AB18: =G18+J18+M18+P18+S18+V18+Y18 -> 51 | AC18: =I18+L18+O18+R18+U18+X18+234 -> 14094 | AD18: 46002 | AF18: нет в потребности
A19: 16 | B19: Дзюдо (юниоры) | D19: 46126 | E19: 46128 | F19: г. Армавир | G19: 1 | H19: 3400 | I19: =G19*H19 -> 3400 | J19: 1 | K19: 3000 | L19: =J19*K19 -> 3000 | M19: 1 | N19: 2900 | O19: =M19*N19 -> 2900 | P19: 9 | Q19: 190 | R19: =P19*Q19 -> 1710 | S19: 9 | T19: 190 | U19: =S19*T19 -> 1710 | V19: 18 | W19: 190 | X19: =V19*W19 -> 3420 | Y19: 39 | Z19: 6 | AA19: =Y19*Z19 -> 234 | AB19: =G19+J19+M19+P19+S19+V19+Y19 -> 78 | AC19: =I19+L19+O19+R19+U19+X19+234 -> 16374
A20: 17 | B20: Дзюдо (юниорки) | D20: 46126 | E20: 46128 | F20: г. Армавир | G20: 1 | H20: 3400 | I20: =G20*H20 -> 3400 | J20: 1 | K20: 3000 | L20: =J20*K20 -> 3000 | M20: 1 | N20: 2900 | O20: =M20*N20 -> 2900 | P20: 8 | Q20: 190 | R20: =P20*Q20 -> 1520 | S20: 8 | T20: 190 | U20: =S20*T20 -> 1520 | V20: 16 | W20: 190 | X20: =V20*W20 -> 3040 | Y20: 35 | Z20: 6 | AA20: =Y20*Z20 -> 210 | AB20: =G20+J20+M20+P20+S20+V20+Y20+35 -> 105 | AC20: =I20+L20+O20+R20+U20+X20+210 -> 15590
A21: 18 | B21: Легкая атлетика | D21: 46171 | E21: 46173 | F21: г. Краснодар | G21: 1 | H21: 3400 | I21: =G21*H21 -> 3400 | J21: 1 | K21: 3000 | L21: =J21*K21 -> 3000 | M21: 1 | N21: 2900 | O21: =M21*N21 -> 2900 | P21: 40 | Q21: 190 | R21: =P21*Q21 -> 7600 | S21: 40 | T21: 190 | U21: =S21*T21 -> 7600 | V21: 40 | W21: 190 | X21: =V21*W21 -> 7600 | Y21: 123 | Z21: 6 | AA21: =Y21*Z21 -> 738 | AB21: =G21+J21+M21+P21+S21+V21+Y21 -> 246 | AC21: =I21+L21+O21+R21+U21+X21+234 -> 32334 | AD21: 46002
A22: 19 | B22: Теннис (юноши) | D22: 46110 | E22: 46117 | F22: г.Кореновск | G22: 1 | H22: 3400 | I22: =G22*H22 -> 3400 | J22: 1 | K22: 3000 | L22: =J22*K22 -> 3000 | M22: 1 | N22: 2900 | O22: =M22*N22 -> 2900 | P22: 3 | Q22: 190 | R22: =P22*Q22 -> 570 | S22: 3 | T22: 190 | U22: =S22*T22 -> 570 | V22: 3 | W22: 190 | X22: =V22*W22 -> 570 | Y22: 12 | Z22: 6 | AA22: =Y22*Z22 -> 72 | AB22: =G22+J22+M22+P22+S22+V22+Y22 -> 24 | AC22: =I22+L22+O22+R22+U22+X22+234 -> 11244 | AD22: 46002 | AE22: 46002 | AF22: 46002
A23: 20 | B23: Теннис (девушки) | D23: 46110 | E23: 46117 | F23: г.Кореновск | G23: 1 | H23: 3400 | I23: =G23*H23 -> 3400 | J23: 1 | K23: 3000 | L23: =J23*K23 -> 3000 | M23: 1 | N23: 2900 | O23: =M23*N23 -> 2900 | P23: 3 | Q23: 190 | R23: =P23*Q23 -> 570 | S23: 3 | T23: 190 | U23: =S23*T23 -> 570 | V23: 3 | W23: 190 | X23: =V23*W23 -> 570 | Y23: 12 | Z23: 6 | AA23: =Y23*Z23 -> 72 | AB23: =G23+J23+M23+P23+S23+V23+Y23 -> 24 | AC23: =I23+L23+O23+R23+U23+X23+234 -> 11244 | AD23: 46002 | AE23: 46002 | AF23: 46002
A24: 21 | B24: Прыжки на батуте | D24: 46132 | E24: 46135 | F24: г. Краснодар | G24: 1 | H24: 3400 | I24: =G24*H24 -> 3400 | J24: 1 | K24: 3000 | L24: =J24*K24 -> 3000 | M24: 1 | N24: 2900 | O24: =M24*N24 -> 2900 | P24: 10 | Q24: 190 | R24: =P24*Q24 -> 1900 | S24: 10 | T24: 190 | U24: =S24*T24 -> 1900 | V24: 10 | W24: 190 | X24: =V24*W24 -> 1900 | Y24: 30 | Z24: 6 | AA24: =Y24*Z24 -> 180 | AB24: =G24+J24+M24+P24+S24+V24+Y24 -> 63 | AC24: =I24+L24+O24+R24+U24+X24+234 -> 15234 | AD24: 46002 | AE24: 46002 | AF24: 46002
A25: 22 | B25: Пулевая стрельба | D25: 46182 | E25: 46185 | F25: г. Краснодар | G25: 1 | H25: 3400 | I25: =G25*H25 -> 3400 | J25: 1 | K25: 3000 | L25: =J25*K25 -> 3000 | M25: 1 | N25: 2900 | O25: =M25*N25 -> 2900 | P25: 8 | Q25: 190 | R25: =P25*Q25 -> 1520 | S25: 8 | T25: 190 | U25: =S25*T25 -> 1520 | V25: 12 | W25: 190 | X25: =V25*W25 -> 2280 | Y25: 31 | Z25: 6 | AA25: =Y25*Z25 -> 186 | AB25: =G25+J25+M25+P25+S25+V25+Y25 -> 62 | AC25: =I25+L25+O25+R25+U25+X25+AA25 -> 14806 | AD25: 46002 | AE25: 46002 | AF25: 46002
A26: 23 | B26: Регби-7 (юноши, девушки) | D26: 46116 | E26: 46117 | F26: Красноармейский район, ст-ца Старожестеблиевская | G26: 2 | H26: 3400 | I26: =G26*H26 -> 6800 | J26: 2 | K26: 3000 | L26: =J26*K26 -> 6000 | M26: 2 | N26: 2900 | O26: =M26*N26 -> 5800 | P26: 30 | Q26: 190 | R26: =P26*Q26 -> 5700 | S26: 30 | T26: 190 | U26: =S26*T26 -> 5700 | V26: 30 | W26: 190 | X26: =V26*W26 -> 5700 | Y26: 96 | Z26: 6 | AA26: =Y26*Z26 -> 576 | AB26: =G26+J26+M26+P26+S26+V26+Y26 -> 192 | AC26: =I26+L26+O26+R26+U26+X26+288 -> 35988 | AD26: 46002
A27: 24 | B27: Водное поло (юноши) | D27: 46174 | E27: 46179 | F27: г. Краснодар | G27: 1 | H27: 3400 | I27: =G27*H27 -> 3400 | J27: 1 | K27: 3000 | L27: =J27*K27 -> 3000 | M27: 1 | N27: 2900 | O27: =M27*N27 -> 2900 | P27: 18 | Q27: 190 | R27: =P27*Q27 -> 3420 | S27: 18 | T27: 190 | U27: =S27*T27 -> 3420 | V27: 18 | W27: 190 | X27: =V27*W27 -> 3420 | Y27: 57 | Z27: 6 | AA27: =Y27*Z27 -> 342 | AB27: =G27+J27+M27+P27+S27+V27+Y27+35 -> 149 | AC27: =I27+L27+O27+R27+U27+X27+210 -> 19770 | AD27: 46002
A28: 25 | B28: Спортивная борьба (греко-римская борьба (юноши) | D28: 46087 | E28: 46089 | F28: г. Краснодар | G28: 1 | H28: 3400 | I28: =G28*H28 -> 3400 | J28: 1 | K28: 3000 | L28: =J28*K28 -> 3000 | M28: 1 | N28: 2900 | O28: =M28*N28 -> 2900 | P28: 15 | Q28: 190 | R28: =P28*Q28 -> 2850 | S28: 15 | T28: 190 | U28: =S28*T28 -> 2850 | V28: 30 | W28: 190 | X28: =V28*W28 -> 5700 | Y28: 60 | Z28: 6 | AA28: =Y28*Z28 -> 360 | AB28: =G28+J28+M28+P28+S28+V28+Y28+35 -> 158 | AC28: =I28+L28+O28+R28+U28+X28+210 -> 20910 | AD28: 46002
A29: 26 | B29: Спортивная борьба (вольная борьба (юноши) | D29: 46101 | E29: 46103 | F29: г.Горячий Ключ | G29: 1 | H29: 3400 | I29: =G29*H29 -> 3400 | J29: 1 | K29: 3000 | L29: =J29*K29 -> 3000 | M29: 1 | N29: 2900 | O29: =M29*N29 -> 2900 | P29: 11 | Q29: 190 | R29: =P29*Q29 -> 2090 | S29: 11 | T29: 190 | U29: =S29*T29 -> 2090 | V29: 22 | W29: 190 | X29: =V29*W29 -> 4180 | Y29: 58 | Z29: 6 | AA29: =Y29*Z29 -> 348 | AB29: =G29+J29+M29+P29+S29+V29+Y29+35 -> 140 | AC29: =I29+L29+O29+R29+U29+X29+210 -> 17870 | AD29: 46002
A30: 27 | B30: Спортивная борьба (вольная борьба (девушки) | D30: 46101 | E30: 46103 | F30: г.Горячий Ключ | G30: 1 | H30: 3400 | I30: =G30*H30 -> 3400 | J30: 1 | K30: 3000 | L30: =J30*K30 -> 3000 | M30: 1 | N30: 2900 | O30: =M30*N30 -> 2900 | P30: 11 | Q30: 190 | R30: =P30*Q30 -> 2090 | S30: 11 | T30: 190 | U30: =S30*T30 -> 2090 | V30: 22 | W30: 190 | X30: =V30*W30 -> 4180 | Y30: 58 | Z30: 6 | AA30: =Y30*Z30 -> 348 | AB30: =G30+J30+M30+P30+S30+V30+Y30+35 -> 140 | AC30: =I30+L30+O30+R30+U30+X30+210 -> 17870 | AD30: 46002
A31: 28 | B31: Спортивная гимнастика | D31: 46119 | E31: 46123 | F31: г. Краснодар | G31: 1 | H31: 3400 | I31: =G31*H31 -> 3400 | J31: 1 | K31: 3000 | L31: =J31*K31 -> 3000 | M31: 1 | N31: 2900 | O31: =M31*N31 -> 2900 | P31: 20 | Q31: 190 | R31: =P31*Q31 -> 3800 | S31: 20 | T31: 190 | U31: =S31*T31 -> 3800 | V31: 20 | W31: 190 | X31: =V31*W31 -> 3800 | Y31: 63 | Z31: 6 | AA31: =Y31*Z31 -> 378 | AB31: =G31+J31+M31+P31+S31+V31+Y31 -> 126 | AC31: =I31+L31+O31+R31+U31+X31+234 -> 20934 | AD31: 46002
A32: 29 | B32: Пулевая стрельба | D32: 46182 | E32: 46185 | F32: г. Краснодар | G32: 1 | H32: 3400 | I32: =G32*H32 -> 3400 | J32: 1 | K32: 3000 | L32: =J32*K32 -> 3000 | M32: 1 | N32: 2900 | O32: =M32*N32 -> 2900 | P32: 8 | Q32: 190 | R32: =P32*Q32 -> 1520 | S32: 8 | T32: 190 | U32: =S32*T32 -> 1520 | V32: 12 | W32: 190 | X32: =V32*W32 -> 2280 | Y32: 31 | Z32: 6 | AA32: =Y32*Z32 -> 186 | AB32: =G32+J32+M32+P32+S32+V32+Y32 -> 62 | AC32: =I32+L32+O32+R32+U32+X32+234 -> 14854 | AD32: 46002 | AH32: нет в потребности
A33: 30 | B33: Стрельба из лука | D33: 46217 | E33: 46221 | F33: г. Сочи | G33: 1 | H33: 3400 | I33: =G33*H33 -> 3400 | J33: 1 | K33: 3000 | L33: =J33*K33 -> 3000 | M33: 1 | N33: 2900 | O33: =M33*N33 -> 2900 | P33: 20 | Q33: 190 | R33: =P33*Q33 -> 3800 | S33: 20 | T33: 190 | U33: =S33*T33 -> 3800 | V33: 20 | W33: 190 | X33: =V33*W33 -> 3800 | Y33: 33 | Z33: 6 | AA33: =Y33*Z33 -> 198 | AB33: =G33+J33+M33+P33+S33+V33+Y33 -> 96 | AC33: =I33+L33+O33+R33+U33+X33+234 -> 20934 | AD33: 46002
